Workbook

Sheet Assumptions
A1: Historical Financial Data
A2: ($ in billions) | B2: 44196 | C2: 44561 | D2: 44926 | E2: 45291 | F2: 45657 | G2: Average
A3: Revenue | B3: 33 | C3: 38.7 | D3: 43 | E3: 45.8 | F3: 47.1 | G3: =((F3/B3)^(1/4)-1) -> 0.09301656 | H3: CAGR
A4: Revenue Growth % | B4: - | C4: 0.171 | D4: 0.113 | E4: 0.064 | F4: 0.029
A5: Gross Profit | B5: 19.6 | C5: 23.3 | D5: 25 | E5: 27.2 | F5: 28.7
A6: Gross Margin % | B6: 0.593 | C6: 0.603 | D6: 0.581 | E6: 0.595 | F6: 0.611 | G6: =AVERAGE(B6:F6) -> 0.5966
A7: EBITDA | B7: 10.5 | C7: 13.4 | D7: 14.2 | E7: 15.3 | F7: 16.3
A8: EBITDA Margin % | B8: 0.317 | C8: 0.348 | D8: 0.331 | E8: 0.335 | F8: 0.347 | G8: =AVERAGE(B8:F8) -> 0.3356
A9: Depreciation & Amortization | B9: 1.5 | C9: 1.5 | D9: 1.5 | E9: 1.6 | F9: 1.8
A10: D&A as % of Revenue | B10: 0.047 | C10: 0.038 | D10: 0.034 | E10: 0.036 | F10: 0.038 | G10: =AVERAGE(B10:F10) -> 0.0386
A11: EBIT | B11: 9 | C11: 11.9 | D11: 12.7 | E11: 13.7 | F11: 14.5
A12: EBIT Margin % | B12: 0.27 | C12: 0.31 | D12: 0.295 | E12: 0.3 | F12: 0.309 | G12: =AVERAGE(B12:F12) -> 0.2968
A13: Taxes | B13: 1.8 | C13: 2.5 | D13: 2.6 | E13: 2.8 | F13: 3
A14: Tax Rate % | B14: 0.2 | C14: 0.21 | D14: 0.205 | E14: 0.204 | F14: 0.207 | G14: =AVERAGE(B14:F14) -> 0.2052
A15: NOPAT | B15: 7.2 | C15: 9.4 | D15: 10.1 | E15: 10.9 | F15: 11.5
A17: Working Capital Assumptions
A18: ($ in billions) | B18: 44196 | C18: 44561 | D18: 44926 | E18: 45291 | F18: 45657 | G18: Average
A19: Accounts Receivable | B19: 3.1 | C19: 3.5 | D19: 3.5 | E19: 3.8 | F19: 3.9 | G19: =AVERAGE(B19,F19) -> 3.5
A20: Inventory | B20: 3.3 | C20: 3.4 | D20: 3.4 | E20: 3.6 | F20: 3.7 | G20: =AVERAGE(B20:F20) -> 3.48
A21: Accounts Payable | B21: 3.1 | C21: 3.4 | D21: 3.9 | E21: 4.4 | F21: 4.3 | G21: =AVERAGE(B21:F21) -> 3.82
A22: Net Working Capital | B22: 3.3 | C22: 3.5 | D22: 3 | E22: 3 | F22: 3.3 | G22: =AVERAGE(B22:F22) -> 3.22
A24: Days Sales Outstanding (DSO) | B24: 34.8 | C24: 33.1 | D24: 29.6 | E24: 30.3 | F24: 30.2 | G24: =AVERAGE(B24:F24) -> 31.6
A25: Days Inventory Outstanding (DIO) | B25: 36.1 | C25: 32.2 | D25: 29 | E25: 28.8 | F25: 28.9 | G25: =AVERAGE(B25:F25) -> 31
A26: Days Payable Outstanding (DPO) | B26: 34.2 | C26: 32.4 | D26: 32.8 | E26: 35.1 | F26: 33.4 | G26: =AVERAGE(B26:F26) -> 33.58
A27: Cash Conversion Cycle | B27: 36.7 | C27: 32.9 | D27: 25.8 | E27: 24 | F27: 25.7 | G27: =AVERAGE(B27:F27) -> 29.02
A31: Capex Assumptions
A32: ($ in billions) | B32: 44196 | C32: 44561 | D32: 44926 | E32: 45291 | F32: 45657 | G32: Average
A33: Capital Expenditures | B33: 1.2 | C33: 1.4 | D33: 1.5 | E33: 1.9 | F33: 2.1 | G33: =AVERAGE(B33:F33) -> 1.62
A34: Capex as % of Revenue | B34: 0.036 | C34: 0.035 | D34: 0.035 | E34: 0.041 | F34: 0.044 | G34: =AVERAGE(B34:F34) -> 0.0382
A35: Maintenance Capex % | B35: 0.6 | C35: 0.6 | D35: 0.6 | E35: 0.6 | F35: 0.6 | G35: =AVERAGE(B35:F35) -> 0.6
A36: Growth Capex % | B36: 0.4 | C36: 0.4 | D36: 0.4 | E36: 0.4 | F36: 0.4 | G36: =AVERAGE(B36:F36) -> 0.4
A37: Maintenance Capex ($B) | B37: 0.7 | C37: 0.8 | D37: 0.9 | E37: 1.1 | F37: 1.2 | G37: =AVERAGE(B37:F37) -> 0.94
A38: Growth Capex ($B) | B38: 0.5 | C38: 0.6 | D38: 0.6 | E38: 0.8 | F38: 0.8 | G38: =AVERAGE(B38:F38) -> 0.66
A41: WACC Calculation
A42: Component | B42: Value
A43: Risk-Free Rate | B43: 0.0423
A44: Beta (5Y Monthly) | B44: 0.39
A45: Equity Risk Premium | B45: 0.06
A46: Cost of Equity | B46: 0.0657
A48: Pre-Tax Cost of Debt | B48: 0.0349
...

Sheet Historical data
A1: Income Statement ($B) | B1: 44196 | C1: 44561 | D1: 44926 | E1: 45291 | F1: 45657
A2: Net Operating Revenues | B2: 33 | C2: 38.7 | D2: 43 | E2: 45.8 | F2: 47.1
A3: Cost of Goods Sold | B3: 13.4 | C3: 15.4 | D3: 18 | E3: 18.5 | F3: 18.4
A4: Gross Profit | B4: 19.6 | C4: 23.3 | D4: 25 | E4: 27.2 | F4: 28.7
A5: Selling, General & Admin | B5: 9.7 | C5: 10.6 | D5: 11.5 | E5: 12.1 | F5: 12.3
A6: Advertising | B6: 2.8 | C6: 3.3 | D6: 4 | E6: 4.1 | F6: 4.3
A7: Other Operating Expenses | B7: 1.7 | C7: 2 | D7: 1.9 | E7: 2 | F7: 2.1
A8: Operating Income | B8: 5.1 | C8: 7.5 | D8: 7.6 | E8: 9 | F8: 10
A9: Interest Income | B9: 0.1 | C9: 0.2 | D9: 0.2 | E9: 0.4 | F9: 0.5
A10: Interest Expense | B10: 1.4 | C10: 1.6 | D10: 1.6 | E10: 1.9 | F10: 1.9
A11: Other Income/(Expense) | B11: -0.6 | C11: 0.6 | D11: -0.6 | E11: -0.7 | F11: -0.8
A12: Income Before Taxes | B12: 3.2 | C12: 6.7 | D12: 5.6 | E12: 6.8 | F12: 7.8
... A18: Balance Sheet ($B) | B18: 44196 | C18: 44561 | D18: 44926 | E18: 45291 | F18: 45657
A19: ASSETS
A20: Cash & Cash Equivalents | B20: 6.8 | C20: 9.6 | D20: 10 | E20: 9.4 | F20: 9
A21: Short-Term Investments | B21: 0.1 | C21: 0.1 | D21: 0.1 | E21: 0.1 | F21: 0.1
A22: Accounts Receivable | B22: 3.1 | C22: 3.5 | D22: 3.5 | E22: 3.8 | F22: 3.9
A23: Inventories | B23: 3.3 | C23: 3.4 | D23: 3.4 | E23: 3.6 | F23: 3.7
A24: Prepaid Expenses & Other | B24: 2 | C24: 2.2 | D24: 2.2 | E24: 2.4 | F24: 2.5
A25: Total Current Assets | B25: 15.3 | C25: 18.8 | D25: 19.2 | E25: 19.3 | F25: 19.2
A26: Equity Method Investments | B26: 17.5 | C26: 18.6 | D26: 19.9 | E26: 20.2 | F26: 20.3
A27: Property, Plant & Equipment | B27: 10.8 | C27: 9.9 | D27: 9.7 | E27: 9.6 | F27: 9.4
A28: Goodwill | B28: 10.3 | C28: 10.3 | D28: 10.3 | E28: 10.3 | F28: 10.4
A29: Other Intangible Assets | B29: 13.8 | C29: 13.5 | D29: 13.3 | E29: 13.2 | F29: 13.1
A30: Other Assets | B30: 19.6 | C30: 23.3 | D30: 20.4 | E30: 25.1 | F30: 27.9
A31: Total Assets | B31: 87.3 | C31: 94.4 | D31: 92.8 | E31: 97.7 | F31: 100.3
A33: LIABILITIES & EQUITY
A34: Accounts Payable | B34: 3.1 | C34: 3.4 | D34: 3.9 | E34: 4.4 | F34: 4.3
A35: Accrued Expenses | B35: 3.5 | C35: 3.9 | D35: 3.8 | E35: 4 | F35: 4.1
A36: Short-Term Debt | B36: 2.2 | C36: 3.3 | D36: 2.5 | E36: 4 | F36: 4.9
A37: Current Portion of Long-Term Debt | B37: 0.5 | C37: 0.5 | D37: 0.5 | E37: 0.5 | F37: 0.5
A38: Other Current Liabilities | B38: 2.9 | C38: 3 | D38: 2.9 | E38: 3 | F38: 3.1
A39: Total Current Liabilities | B39: 12.2 | C39: 14.1 | D39: 13.6 | E39: 15.9 | F39: 16.9
A40: Long-Term Debt | B40: 37.6 | C40: 34.3 | D40: 32.4 | E40: 35.3 | F40: 34.1
A41: Other Liabilities | B41: 18.2 | C41: 22 | D41: 20.9 | E41: 20.4 | F41: 22.4
A42: Total Liabilities | B42: 68 | C42: 70.4 | D42: 66.9 | E42: 71.6 | F42: 73.4
A43: Total Equity | B43: 19.3 | C43: 24 | D43: 25.9 | E43: 26.1 | F43: 26.9
A44: Total Liabilities & Equity | B44: 87.3 | C44: 94.4 | D44: 92.8 | E44: 97.7 | F44: 100.3
A48: Cash Flow Statement ($B) | B48: 44196 | C48: 44561 | D48: 44926 | E48: 45291 | F48: 45657
A49: CASH FROM OPERATIONS
...

Sheet Income Statement (5-year projec
A1: Revenue Build ($B) | B1: 2025 | C1: 2026 | D1: 2027 | E1: 2028 | F1: 2029 | G1: Formula Reference
A2: Prior Year Revenue | B2: 47.1 | C2: =SUM(C7:C11) -> 51.145 | D2: =SUM(D7:D11) -> 53.445 | E2: =SUM(E7:E11) -> 55.54 | F2: =SUM(F7:F11) -> 57.435 | G2: From 2024 actual or prior year
A3: Base Growth Rate | B3: 0.04 | C3: 0.045 | D3: 0.045 | E3: 0.04 | F3: 0.035 | G3: From Tab 1 A72-A77
A4: Organic Growth | B4: 1.9 | C4: 2.2 | D4: 2.3 | E4: 2 | F4: 1.7 | G4: PriorRevenue*BaseGrowth
A5: Pricing Power | B5: 0.5 | C5: 0.6 | D5: 0.6 | E5: 0.5 | F5: 0.4 | G5: 1% of prior revenue
A6: FX Impact | B6: - | C6: - | D6: - | E6: - | F6: - | G6: ±1-2%
A7: Acquisitions | B7: - | C7: - | D7: - | E7: - | F7: - | G7: M&A assumption (base case = 0)
A8: Total Revenue | B8: 48.9 | C8: 51.1 | D8: 53.4 | E8: 55.5 | F8: 57.4 | G8: Organic+Pricing+FX+Acquisitions
A9: Revenue Growth % | B9: 0.04 | C9: 0.045 | D9: 0.045 | E9: 0.04 | F9: 0.035 | G9: (Current-Prior)/Prior
A15: Income Statement ($B) | B15: 2025 | C15: 2026 | D15: 2027 | E15: 2028 | F15: 2029 | G15: Formula refernce
A16: Net Operating Revenues | B16: 48.9 | C16: 51.1 | D16: 53.4 | E16: 55.5 | F16: 57.4 | G16: From Revenue Build above
A17: Cost of Goods Sold | B17: 19.1 | C17: 19.9 | D17: 20.8 | E17: 21.6 | F17: 22.4 | G17: Revenue*(1-GrossMargin%)
A18: Gross Profit | B18: 29.8 | C18: 31.2 | D18: 32.6 | E18: 33.9 | F18: 35.1 | G18: Revenue-COGS
A19: Gross Margin % | B19: 0.61 | C19: 0.61 | D19: 0.61 | E19: 0.61 | F19: 0.61 | G19: =Assumptions!$C$80 -> 0.595
A21: Selling, General & Admin | B21: 14.7 | C21: 15.3 | D21: 16 | E21: 16.6 | F21: 17.2 | G21: =30% of Revenue (industry avg)
A22: Advertising | B22: 4.9 | C22: 5.1 | D22: 5.3 | E22: 5.6 | F22: 5.7 | G22: =10% of Revenue
A23: Other Operating Expenses | B23: 2.4 | C23: 2.6 | D23: 2.7 | E23: 2.8 | F23: 2.9 | G23: =5% of Revenue
A24: Total Operating Expenses | B24: 22 | C24: 23 | D24: 24 | E24: 25 | F24: 25.8
A26: EBITDA | B26: 16.9 | C26: 17.6 | D26: 18.4 | E26: 19.1 | F26: 19.7
A27: EBITDA Margin % | B27: 0.345 | C27: 0.345 | D27: 0.345 | E27: 0.345 | F27: 0.345 | G27: =Assumptions!$C$81 -> 0.32
A29: Depreciation & Amortization | B29: 1.9 | C29: 1.9 | D29: 2 | E29: 2.1 | F29: 2.2 | G29: Revenue*D&A%
A30: D&A % of Revenue | B30: 0.038 | C30: 0.038 | D30: 0.038 | E30: 0.038 | F30: 0.038 | G30: =Assumptions!$C$83 -> 0.038
A32: EBIT | B32: 15 | C32: 15.7 | D32: 16.4 | E32: 17 | F32: 17.6 | G32: =EBITDA-D&A
A33: EBIT Margin % | B33: 0.305 | C33: 0.305 | D33: 0.305 | E33: 0.305 | F33: 0.305 | G33: =Assumptions!$C$82 -> 0.28
A35: Interest Income | B35: 0.5 | C35: 0.5 | D35: 0.5 | E35: 0.6 | F35: 0.6 | G35: =Cash*2% (assumed yield)
A36: Interest Expense | B36: 2 | C36: 2 | D36: 2 | E36: 2 | F36: 2 | G36: =AvgDebt*5% (assumed rate)
A37: Net Interest Expense | B37: 1.5 | C37: 1.5 | D37: 1.5 | E37: 1.4 | F37: 1.4 | G37: =IntExp-IntIncome
A39: Income Before Taxes | B39: 13.5 | C39: 14.2 | D39: 14.9 | E39: 15.6 | F39: 16.2 | G39: =EBIT-NetInterest
A40: Income Taxes | B40: 2.8 | C40: 2.9 | D40: 3.1 | E40: 3.2 | F40: 3.3 | G40: =EBT*TaxRate%
A41: Tax Rate | B41: 0.205 | C41: 0.205 | D41: 0.205 | E41: 0.205 | F41: 0.205 | G41: =Assumptions!$C$84 -> 0.205
A43: Net Income | B43: 10.7 | C43: 11.3 | D43: 11.8 | E43: 12.4 | F43: 12.9 | G43: =EBT-Taxes
A44: Net Margin % | B44: 0.219 | C44: 0.221 | D44: 0.221 | E44: 0.223 | F44: 0.225 | G44: =NetIncome/Revenue
A49: Per Share Metrics | B49: 2025 | C49: 2026 | D49: 2027 | E49: 2028 | F49: 2029 | G49: Formula Reference
A50: Diluted Shares Outstanding (B) | B50: 4.3 | C50: 4.3 | D50: 4.3 | E50: 4.3 | F50: 4.3 | G50: =Assumptions!$F$64 (flat assumption)
A51: Weighted Avg Shares | B51: 4.3 | C51: 4.3 | D51: 4.3 | E51: 4.3 | F51: 4.3 | G51: =Average of beginning and ending
A53: EPS - Basic | B53: $2.49 | C53: $2.63 | D53: $2.74 | E53: $2.88 | F53: $3.00 | G53: =NetIncome/Shares
A54: EPS - Diluted | B54: $2.49 | C54: $2.63 | D54: $2.74 | E54: $2.88 | F54: $3.00 | G54: =NetIncome/DilutedShares
A56: Dividends per Share | B56: $2.04 | C56: $2.14 | D56: $2.25 | E56: $2.36 | F56: $2.48 | G56: =PriorDPS*(1+5% growth)
A57: Dividend Payout Ratio | B57: 0.82 | C57: 0.81 | D57: 0.82 | E57: 0.82 | F57: 0.83 | G57: =TotalDividends/NetIncome
A58: Total Dividends Paid | B58: $8.8 | C58: $9.2 | D58: $9.7 | E58: $10.2 | F58: $10.7 | G58: =DPS*Shares
...

Sheet  Balance Sheet (5-year projecti
A1: Assets ($B) | B1: 2025 | C1: 2026 | D1: 2027 | E1: 2028 | F1: 2029 | G1: 'Formula Reference
A2: CURRENT ASSETS
A3: Cash & Cash Equivalents | B3: 9.5 | C3: 10.2 | D3: 11 | E3: 11.8 | F3: 12.7 | G3: {=Prior+FCF-Dividends-Repurchases+NetDebtChanges} -> #NAME?
A4: Short-Term Investments | B4: 0.1 | C4: 0.1 | D4: 0.1 | E4: 0.1 | F4: 0.1 | G4: Flat assumption
A5: Accounts Receivable | B5: 4.2 | C5: 4.4 | D5: 4.6 | E5: 4.8 | F5: 5 | G5: =(DSO/365)*Revenue from Tab 3
A6: Inventories | B6: 3.9 | C6: 4.1 | D6: 4.3 | E6: 4.4 | F6: 4.6 | G6: =(DIO/365)*COGS from Tab 3
A7: Prepaid Expenses & Other | B7: 2.6 | C7: 2.7 | D7: 2.8 | E7: 2.9 | F7: 3 | G7: =5.3% of Revenue
A8: Total Current Assets | B8: 20.3 | C8: 21.5 | D8: 22.8 | E8: 24 | F8: 25.4 | G8: Sum of above
A10: NON-CURRENT ASSETS
A11: Equity Method Investments | B11: 20.5 | C11: 20.7 | D11: 20.9 | E11: 21.1 | F11: 21.3 | G11: Growth with GDP (~1% annually)
A12: Property, Plant & Equipment | B12: 9.2 | C12: 9 | D12: 8.8 | E12: 8.6 | F12: 8.4 | G12: =PriorPP&E+Capex-D&A from Tab 3
A13: Goodwill | B13: 10.4 | C13: 10.4 | D13: 10.4 | E13: 10.4 | F13: 10.4 | G13: No M&A assumption (flat)
A14: Other Intangible Assets | B14: 12.9 | C14: 12.7 | D14: 12.5 | E14: 12.3 | F14: 12.1 | G14: =Prior-Amortization from Tab 3
A15: Other Assets | B15: 28.5 | C15: 29.5 | D15: 30.5 | E15: 31.5 | F15: 32.5 | G15: Growth with revenue
A16: Total Non-Current Assets | B16: 81.5 | C16: 82.3 | D16: 83.1 | E16: 83.9 | F16: 84.7 | G16: Sum of above
A18: TOTAL ASSETS | B18: 101.8 | C18: 103.8 | D18: 105.9 | E18: 107.9 | F18: 110.1 | G18: =CurrentAssets+NonCurrentAssets
A23: Liabilities ($B) | B23: 2025 | C23: 2026 | D23: 2027 | E23: 2028 | F23: 2029 | G23: 'Formula Reference
A24: CURRENT LIABILITIES
A25: Accounts Payable | B25: 4.6 | C25: 4.8 | D25: 5 | E25: 5.2 | F25: 5.4 | G25: =(DPO/365)*COGS from Tab 3
A26: Accrued Expenses | B26: 4.2 | C26: 4.4 | D26: 4.6 | E26: 4.8 | F26: 5 | G26: =8.7% of Revenue
A27: Short-Term Debt | B27: 4.9 | C27: 4.9 | D27: 4.9 | E27: 4.9 | F27: 4.9 | G27: Flat (refinancing assumption)
A28: Current Portion of Long-Term Debt | B28: 0.5 | C28: 0.5 | D28: 0.5 | E28: 0.5 | F28: 0.5 | G28: Flat
A29: Other Current Liabilities | B29: 3.2 | C29: 3.3 | D29: 3.5 | E29: 3.6 | F29: 3.8 | G29: =6.5% of Revenue
A30: Total Current Liabilities | B30: 17.4 | C30: 18 | D30: 18.5 | E30: 19.1 | F30: 19.6 | G30: Sum of above
A32: NON-CURRENT LIABILITIES
A33: Long-Term Debt | B33: 34.1 | C33: 33.1 | D33: 32.1 | E33: 31.1 | F33: 30.1 | G33: =Prior-ScheduledRepayments+NewIssuances
A34: Deferred Tax Liabilities | B34: 2.5 | C34: 2.6 | D34: 2.7 | E34: 2.8 | F34: 2.9 | G34: Growth with timing differences
A35: Other Liabilities | B35: 22.8 | C35: 23.5 | D35: 24.2 | E35: 24.9 | F35: 25.6 | G35: =48% of Revenue
A36: Total Non-Current Liabilities | B36: 59.4 | C36: 59.2 | D36: 59 | E36: 58.8 | F36: 58.6 | G36: Sum of above
A38: TOTAL LIABILITIES | B38: 76.8 | C38: 77.2 | D38: 77.5 | E38: 77.9 | F38: 78.2 | G38: =Current+NonCurrent
A42: Equity ($B) | B42: 2025 | C42: 2026 | D42: 2027 | E42: 2028 | F42: 2029 | G42: 'Formula Reference
A43: Common Stock | B43: 0 | C43: 0 | D43: 0 | E43: 0 | F43: 0 | G43: No new issuance (flat)
A44: Additional Paid-In Capital | B44: 0 | C44: 0 | D44: 0 | E44: 0 | F44: 0 | G44: Flat
A45: Retained Earnings | B45: 24.9 | C45: 27 | D45: 29.2 | E45: 31.5 | F45: 33.9 | G45: {=Prior+NetIncome-Dividends} -> #NAME?
A46: Treasury Stock | B46: -0.5 | C46: -0.5 | D46: -0.5 | E46: -0.5 | F46: -0.5 | G46: Flat (repurchases netted in retained earnings)
A47: Accumulated Other Comprehensive Income | B47: 0.6 | C47: 0.6 | D47: 0.6 | E47: 0.6 | F47: 0.6 | G47: Flat assumption
A48: Total Equity | B48: 25 | C48: 27.1 | D48: 29.3 | E48: 31.6 | F48: 34 | G48: Sum of above
A50: TOTAL LIABILITIES & EQUITY | B50: 101.8 | C50: 103.8 | D50: 105.9 | E50: 107.9 | F50: 110.1 | G50: {=Liabilities+Equity} -> #NAME?
A52: BALANCE CHECK | B52: 0 | C52: 0 | D52: 0 | E52: 0 | F52: 0 | G52: =Assets-(Liab+Equity) should be 0
A56: Working Capital Summary | B56: 2025 | C56: 2026 | D56: 2027 | E56: 2028 | F56: 2029 | G56: 'Formula Reference
...

Sheet Cash Flow Statement (5-year pro
A1: Cash Flow from Operations ($B) | B1: 2025 | C1: 2026 | D1: 2027 | E1: 2028 | F1: 2029 | G1: 'Formula Reference
A2: Net Income | B2: 10.7 | C2: 11.3 | D2: 11.8 | E2: 12.4 | F2: 12.9 | G2: From Income Statement Tab 3
A3: Adjustments to Reconcile Net Income to Cash:
A4: Depreciation & Amortization | B4: 1.9 | C4: 1.9 | D4: 2 | E4: 2.1 | F4: 2.2 | G4: From Income Statement Tab 3
A5: Stock-Based Compensation | B5: 0.4 | C5: 0.4 | D5: 0.4 | E5: 0.4 | F5: 0.4 | G5: Assumption: $0.4B/year
A6: Deferred Income Taxes | B6: -0.1 | C6: -0.1 | D6: -0.1 | E6: -0.1 | F6: -0.1 | G6: Assumption: flat
A7: Equity Income - Net of Dividends | B7: -0.9 | C7: -0.9 | D7: -0.9 | E7: -0.9 | F7: -0.9 | G7: From Income Statement (Other Income)
A8: Foreign Currency Adjustments | B8: 0 | C8: 0 | D8: 0 | E8: 0 | F8: 0 | G8: Base case = 0
A9: Significant Gains/Losses | B9: 0.3 | C9: 0.3 | D9: 0.3 | E9: 0.3 | F9: 0.3 | G9: Assumption: flat
A10: Changes in Operating Assets and Liabilities:
A11: Accounts Receivable | B11: -0.3 | C11: -0.2 | D11: -0.2 | E11: -0.2 | F11: -0.2 | G11: =PriorAR-CurrentAR (from Balance Sheet)
A12: Inventories | B12: -0.2 | C12: -0.2 | D12: -0.2 | E12: -0.1 | F12: -0.2 | G12: =PriorInv-CurrentInv
A13: Prepaid Expenses & Other | B13: -0.1 | C13: -0.1 | D13: -0.1 | E13: -0.1 | F13: -0.1 | G13: =Change in Prepaid
A14: Accounts Payable and Accrued Expenses | B14: 0.4 | C14: 0.4 | D14: 0.4 | E14: 0.4 | F14: 0.4 | G14: =CurrentAP-PriorAP
A15: Other Liabilities | B15: 0.5 | C15: 0.5 | D15: 0.5 | E15: 0.5 | F15: 0.5 | G15: =Change in Other Liab
A16: Total Changes in Working Capital | B16: 0.3 | C16: 0.4 | D16: 0.4 | E16: 0.5 | F16: 0.4 | G16: Sum of WC changes
A18: Net Cash Provided by Operating Activities | B18: 12.6 | C18: 13.3 | D18: 13.9 | E18: 14.6 | F18: 15.1 | G18: =NetIncome+D&A+SBC+WCChanges+Other
A21: Cash Flow from Investing ($B) | B21: 2025 | C21: 2026 | D21: 2027 | E21: 2028 | F21: 2029 | G21: 'Formula Reference
A22: Purchases of Property, Plant & Equipment | B22: 2.2 | C22: 2.3 | D22: 2.4 | E22: 2.5 | F22: 2.6 | G22: =Revenue*Capex% from Assumptions
A23: Proceeds from Disposals of PP&E | B23: 0.1 | C23: 0.1 | D23: 0.1 | E23: 0.1 | F23: 0.1 | G23: Assumption: $0.1B/year
A24: Acquisitions | B24: 0 | C24: 0 | D24: 0 | E24: 0 | F24: 0 | G24: Base case: no M&A
A25: Purchases of Investments | B25: 4.5 | C25: 4.7 | D25: 4.9 | E25: 5.1 | F25: 5.3 | G25: Growth with revenue
... A54: Cash at End of Year | B54: 8.2 | C54: 7.6 | D54: 7 | E54: 6.5 | F54: 5.9 | G54: =BegCash+NetChange
A56: RECONCILIATION CHECK
A57: Cash from Balance Sheet | B57: 9.5 | C57: 10.2 | D57: 11 | E57: 11.8 | F57: 12.7 | G57: From Tab 4 (should match End Cash)
A58: Difference | B58: -1.3 | C58: -2.6 | D58: -4 | E58: -5.3 | F58: -6.8 | G58: =BalanceSheetCash-EndCash (should be 0)
A63: Free Cash Flow Build ($B) | B63: 2025 | C63: 2026 | D63: 2027 | E63: 2028 | F63: 2029 | G63: 'Formula Reference
A64: Net Income | B64: 10.7 | C64: 11.3 | D64: 11.8 | E64: 12.4 | F64: 12.9 | G64: From Income Statement
A65: Plus: Depreciation & Amortization | B65: 1.9 | C65: 1.9 | D65: 2 | E65: 2.1 | F65: 2.2 | G65: From Income Statement
A66: Plus: Stock-Based Compensation | B66: 0.4 | C66: 0.4 | D66: 0.4 | E66: 0.4 | F66: 0.4 | G66: From above
A67: Less: Change in Working Capital | B67: -0.3 | C67: -0.4 | D67: -0.4 | E67: -0.5 | F67: -0.4 | G67: From above (negative = use of cash)
A68: Less: Capital Expenditures | B68: 2.2 | C68: 2.3 | D68: 2.4 | E68: 2.5 | F68: 2.6 | G68: From above
A70: Unlevered Free Cash Flow | B70: 10.5 | C70: 10.9 | D70: 11.4 | E70: 11.9 | F70: 12.3 | G70: {=NetIncome+D&A+SBC-WCChange-Capex} -> #NAME?
A72: Less: Interest Expense (after-tax) | B72: 1.6 | C72: 1.5 | D72: 1.5 | E72: 1.5 | F72: 1.5 | G72: {=IntExp×(1-TaxRate)} -> #NAME?
A73: Plus: Interest Income (after-tax) | B73: 0.4 | C73: 0.4 | D73: 0.4 | E73: 0.4 | F73: 0.4 | G73: {=IntInc×(1-TaxRate)} -> #NAME?
A75: Levered Free Cash Flow | B75: 9.3 | C75: 9.8 | D75: 10.3 | E75: 10.8 | F75: 11.2 | G75: {=UFCF-AfterTaxIntExp+AfterTaxIntInc} -> #NAME?
A77: Less: Dividends | B77: 8.8 | C77: 9.2 | D77: 9.7 | E77: 10.2 | F77: 10.7 | G77: From above
A78: Less: Share Repurchases | B78: 2 | C78: 2 | D78: 2 | E78: 2 | F78: 2 | G78: From above
A79: Plus: Net Debt Issuances | B79: -0.5 | C79: -0.5 | D79: -0.5 | E79: -0.5 | F79: -0.5 | G79: From above (negative = repayment)
A81: Change in Cash | B81: -2 | C81: -1.9 | D81: -1.9 | E81: -1.9 | F81: -2 | G81: {=LFCF-Dividends-Repurchases+NetDebt} -> #NAME?
...

Sheet DCF Valuation
A1: Explicit Period FCF ($B) | B1: 2025 | C1: 2026 | D1: 2027 | E1: 2028 | F1: 2029 | G1: 'Formula Reference
A2: Unlevered Free Cash Flow | B2: 10.5 | C2: 10.9 | D2: 11.4 | E2: 11.9 | F2: 12.3 | G2: From Cash Flow Tab 5
A3: Mid-Year Adjustment | B3: 0.5 | C3: 0.5 | D3: 0.5 | E3: 0.5 | F3: 0.5 | G3: Assumption: 0.5 for mid-year discounting
A4: Adjusted FCF | B4: 10.8 | C4: 11.2 | D4: 11.7 | E4: 12.2 | F4: 12.6 | G4: =UFCF×(1+MidYearAdjustment/2)
A6: WACC | B6: 0.061 | C6: 0.061 | D6: 0.061 | E6: 0.061 | F6: 0.061 | G6: From Assumptions Tab 1
A7: Discount Period | B7: 0.5 | C7: 1.5 | D7: 2.5 | E7: 3.5 | F7: 4.5 | G7: =Year-0.5 (mid-year convention)
A8: Discount Factor | B8: 0.971 | C8: 0.915 | D8: 0.863 | E8: 0.814 | F8: 0.768 | G8: =1/(1+WACC)^DiscountPeriod
A10: Present Value of FCF | B10: 10.5 | C10: 10.2 | D10: 10.1 | E10: 9.9 | F10: 9.7 | G10: =AdjustedFCF×DiscountFactor
A11: Cumulative PV of FCF | B11: 10.5 | C11: 20.7 | D11: 30.8 | E11: 40.7 | F11: 50.4 | G11: Sum of PVs
A16: Terminal Value Calculation | B16: 2025 | C16: 2026 | D16: 2027 | E16: 2028 | F16: 2029 | G16: 'Formula Reference
A17: EBITDA (Year 5) | B17: - | C17: - | D17: - | E17: - | F17: 19.7 | G17: From Income Statement Tab 3
A18: Exit Multiple (EV/EBITDA) | B18: - | C18: - | D18: - | E18: - | F18: 18.0x | G18: From Assumptions Tab 1
A19: Terminal Value | B19: - | C19: - | D19: - | E19: - | F19: 354.6 | G19: {=EBITDA×ExitMultiple} -> #NAME?
A21: Terminal Growth Rate | B21: - | C21: - | D21: - | E21: - | F21: 0.025 | G21: From Assumptions Tab 1
A22: Gordon Growth Check | B22: - | C22: - | D22: - | E22: - | F22: 267.4 | G22: =FCFYear5×(1+g)/(WACC-g)
A23: Implied Exit Multiple | B23: - | C23: - | D23: - | E23: - | F23: 13.6x | G23: =GordonValue/EBITDA
A25: Selected Terminal Value | B25: - | C25: - | D25: - | E25: - | F25: 354.6 | G25: =ExitMultipleMethod (or Gordon if selected)
A26: Discount Factor (Year 5) | B26: - | C26: - | D26: - | E26: - | F26: 0.768 | G26: From above
A27: Present Value of Terminal Value | B27: - | C27: - | D27: - | E27: - | F27: 272.3 | G27: =TerminalValue×DiscountFactor
A30: Enterprise Value Calculation | B30: 2025 | C30: 2026 | D30: 2027 | E30: 2028 | F30: 2029 | G30: 'Formula Reference
A31: Present Value of Explicit FCF | B31: 50.4 | C31: - | D31: - | E31: - | F31: - | G31: From Section 1
A32: Present Value of Terminal Value | B32: 272.3 | C32: - | D32: - | E32: - | F32: - | G32: From Section 2
A33: Enterprise Value | B33: 322.7 | C33: - | D33: - | E33: - | F33: - | G33: {=PVofFCF+PVofTV} -> #NAME?
A35: Plus: Cash & Cash Equivalents | B35: 9.5 | C35: - | D35: - | E35: - | F35: - | G35: From Balance Sheet Tab 4
A36: Less: Total Debt | B36: 39 | C36: - | D36: - | E36: - | F36: - | G36: From Balance Sheet Tab 4
A37: Less: Minority Interest | B37: 0 | C37: - | D37: - | E37: - | F37: - | G37: Assumption: negligible
A38: Less: Preferred Stock | B38: 0 | C38: - | D38: - | E38: - | F38: - | G38: Assumption: none
A39: Plus: Pension Fund Deficit | B39: 0 | C39: - | D39: - | E39: - | F39: - | G39: Assumption: none
A41: Equity Value | B41: 293.2 | C41: - | D41: - | E41: - | F41: - | G41: {=EV+Cash-Debt-MinInt-Pref+Pension} -> #NAME?
A43: Diluted Shares Outstanding (B) | B43: 4.3 | C43: - | D43: - | E43: - | F43: - | G43: From Income Statement Tab 3
A44: Equity Value Per Share | B44: $68.19 | C44: - | D44: - | E44: - | F44: - | G44: {=EquityValue/Shares} -> #NAME?
A48: Sensitivity: WACC vs Exit Multiple | B48: 15.0x | C48: 16.0x | D48: 17.0x | E48: 18.0x | F48: 19.0x | G48: 20.0x
A49: 0.055 | B49: $81.23 | C49: $85.45 | D49: $89.67 | E49: $93.89 | F49: $98.11 | G49: $102.33
A50: 0.06 | B50: $74.56 | C50: $78.34 | D50: $82.12 | E50: $85.90 | F50: $89.68 | G50: $93.46
A51: 0.061 | B51: $72.98 | C51: $76.67 | D51: $80.36 | E51: $84.05 | F51: $87.74 | G51: $91.43
A52: 0.065 | B52: $68.19 | C52: $71.63 | D52: $75.07 | E52: $78.51 | F52: $81.95 | G52: $85.39
A53: 0.07 | B53: $62.34 | C53: $65.45 | D53: $68.56 | E53: $71.67 | F53: $74.78 | G53: $77.89
A54: 0.075 | B54: $56.89 | C54: $59.72 | D54: $62.55 | E54: $65.38 | F54: $68.21 | G54: $71.04
A56: Sensitivity: Revenue Growth vs EBITDA Margin | B56: 0.32 | C56: 0.33 | D56: 0.34 | E56: 0.345 | F56: 0.35 | G56: 0.36
A57: 0.03 | B57: $52.34 | C57: $58.67 | D57: $65.01 | E57: $68.18 | F57: $71.34 | G57: $77.68
...

Sheet Monte Carlo Setup
A1: iteration | B1: revenue_growth_y1 | C1: avg_revenue_growth_y2_5 | D1: ebitda_margin | E1: exit_multiple | F1: wacc | G1: capex_pct | H1: dso | I1: equity_value_per_share
A2: 1 | B2: 0.04745071 | C2: 0.03558713 | D2: 0.34696412 | E2: 17.058674 | F2: 0.057823005 | G2: 0.039888018 | H2: 28.885638 | I2: 58.528136
A3: 2 | B3: 0.03792604 | C3: 0.04193585 | D3: 0.34371784 | E3: 20.794045 | F3: 0.05743295 | G3: 0.04269638 | H3: 32.499382 | I3: 71.892243
A4: 3 | B4: 0.04971533 | C4: 0.04523294 | D4: 0.36403582 | E4: 20.899497 | F4: 0.0693985 | G4: 0.0423727 | H4: 34.065828 | I4: 74.404359
A5: 4 | B5: 0.06284545 | C5: 0.03724835 | D5: 0.37565662 | E5: 18.505887 | F5: 0.05770727 | G5: 0.04138458 | H5: 31.453738 | I5: 70.970631
A6: 5 | B6: 0.0364877 | C6: 0.041393028 | D6: 0.35873694 | E6: 16.987222 | F6: 0.06039212 | G6: 0.041611887 | H6: 33.100272 | I6: 60.347578
A7: 6 | B7: 0.03648795 | C7: 0.05072421 | D7: 0.36523088 | E7: 18.584074 | F7: 0.05468857 | G7: 0.05153053 | H7: 30.416948 | I7: 71.792406
A8: 7 | B8: 0.06368819 | C8: 0.046700408 | D8: 0.34065192 | E8: 20.585072 | F8: 0.05865403 | G8: 0.05416325 | H8: 31.851765 | I8: 73.005863
A9: 8 | B9: 0.05151152 | C9: 0.039943903 | D9: 0.3475081 | E9: 17.816554 | F9: 0.06400685 | G9: 0.05156179 | H9: 31.799709 | I9: 60.327986
A10: 9 | B10: 0.03295788 | C10: 0.03247309 | D10: 0.37471464 | E10: 16.700727 | F10: 0.06440238 | G10: 0.034213036 | H10: 30.899412 | I10: 58.995486
A11: 10 | B11: 0.0481384 | C11: 0.045960877 | D11: 0.35553423 | E11: 19.071404 | F11: 0.06592081 | G11: 0.050389531 | H11: 29.710893 | I11: 67.11226
A12: 11 | B12: 0.03304873 | C12: 0.039315881 | D12: 0.3401594 | E12: 18.897667 | F12: 0.05601181 | G12: 0.048682528 | H12: 30.140698 | I12: 63.807109
A13: 12 | B13: 0.033014054 | C13: 0.03985721 | D13: 0.34565101 | E13: 15.170743 | F13: 0.05763312 | G13: 0.04481386 | H13: 30.229622 | I13: 51.776825
... A10001: 10000 | B10001: 0.049665827 | C10001: 0.04676857 | D10001: 0.34487205 | E10001: 17.427509 | F10001: 0.0529781 | G10001: 0.043158196 | H10001: 29.187167 | I10001: 63.703785

Sheet Results & Charts
